Workbook

Sheet Methodology & Approach
A1: INDEPENDENT ASSESSMENT — METHODOLOGY & APPROACH
A2: BNM RMiT IESP — Data Centre Resilience Assessment (DCRA)
A4: ENGAGEMENT DETAILS
A5: Entity Name: | B5: [Entity Name]
A6: Engagement Type: | B6: Data Centre Resilience Assessment (DCRA)
A7: Regulatory Basis: | B7: Paragraph 14.1, mapped to paragraphs 10.24 to 10.28
A8: Assessment Date: | B8: [DD/MM/YYYY]
A9: Assessment Period: | B9: [Start Date] to [End Date]
A10: Lead Assessor: | B10: [Name, Qualification]
A11: Engagement Reference: | B11: [Ref Number]
A12: Report Classification: | B12: Confidential (Sulit)
A14: SCOPE OF ASSESSMENT
A15: This assessment is conducted pursuant to BNM RMiT (BNM/RH/PD 028-98, 28 Nov 2025), Paragraph 14.1.
A16: Assessment covers: (1) DCRA — DC resilience, redundancy, physical security, operations, segregation (10.24-10.28, 5 domains), (2) Appendix 7 Part D — Minimum Controls.
A18: ENGAGEMENT MODE
A19: Design Adequacy (Pre-Implementation):
A20: Assess whether proposed/planned controls are designed to meet the requirement. Evidence is primarily documentary: architecture designs, policies, vendor assessments, staging test results.
A21: Operating Effectiveness (Independent Attestation):
A22: Assess whether controls operated effectively during the assessment period. Evidence is observation, sampling, re-performance, system-generated logs. Requires defined sampling methodology.
A24: ASSESSMENT LEVELS
A25: ORG | B25: Organisation-level. Assessed once per engagement (policies, governance, frameworks).
A26: PLATFORM | B26: Platform/CSP-level. Assessed per platform in scope (configurations, controls per CSP).
A27: WORKLOAD | B27: System/application-level. Assessed per critical system using sampling.
A29: ASSESSMENT METHODS
A30: Inspection | B30: Examination of documents, records, policies, configurations, and tangible evidence.
A31: Inquiry | B31: Interviews with management, process owners, and staff.
A32: Observation | B32: Direct observation of processes, systems, and activities.
A33: Confirmation | B33: Verification with external or independent parties.
A34: Re-performance | B34: IESP independently re-performs the control procedure.
A36: CONCLUSION SCALE
A37: Compliant | B37: Control fully implemented and operating effectively. Evidence supports regulatory criteria are met.
A38: Partially Compliant | B38: Implemented but with gaps in scope, coverage, documentation, or effectiveness.
A39: Non-Compliant | B39: Absent, fundamentally deficient, or not operating. Regulatory criteria not met.
A40: N/A | B40: Not applicable to entity's operations. Justification documented.
A42: EVIDENCE HIERARCHY (prefer higher-ranked)
A43: Rank 1 | B43: Direct observation — IESP directly observes control in operation
A44: Rank 2 | B44: Independent confirmation — Third-party evidence (SOC 2, certifications)
A45: Rank 3 | B45: System-generated — Logs, configurations without manual intervention
A46: Rank 4 | B46: Re-performance — IESP re-performs control procedure
A47: Rank 5 | B47: Documentary — Policies, procedures, meeting minutes
...

Sheet Scoping
A1: ENGAGEMENT SCOPING — BNM RMiT IESP — Data Centre Resilience Assessment (DCRA)
A3: ASSESSMENT LEVELS
A4: ORG | B4: Organisation / Enterprise level. Assessed ONCE per engagement. Policies, frameworks, governance structures that apply across all platforms and systems.
A5: PLATFORM | B5: Platform / CSP level. Assessed PER PLATFORM in scope. If the FI uses AWS and Azure, repeat these test steps for each. Covers platform-specific configurations and controls.
A6: WORKLOAD | B6: Workload / Application / System level. Assessed PER CRITICAL SYSTEM in scope using sampling. Covers system-specific deployments, configurations, and arrangements.
A8: PLATFORMS / CSPs IN SCOPE
A9: # | B9: Platform / CSP | C9: Service Models (IaaS/PaaS/SaaS) | D9: Regions | E9: Contract Ref | F9: Notes
A10: 1
A11: 2
A12: 3
A13: 4
A14: 5
A16: CRITICAL SYSTEMS / WORKLOADS IN SCOPE
A17: # | B17: System / Application Name | C17: Platform | D17: Criticality | E17: Data Classification | F17: Notes
A18: 1
A19: 2
A20: 3
A21: 4
A22: 5
A23: 6
A24: 7
A25: 8
A26: 9
A27: 10
A29: SAMPLING APPROACH
A30: Assessment Period: | B30: [Start Date] to [End Date]
A31: User Access Samples: | B31: [e.g., 20 user accounts, 10 leavers/transfers]
A32: Change Management Samples: | B32: [e.g., 10 recent changes]
A33: Incident Samples: | B33: [e.g., 15 SOC alerts, all significant incidents in period]
A34: Firewall Rule Samples: | B34: [e.g., 20 rules]
A35: Configuration Samples: | B35: [e.g., 10 network devices]

Sheet Planning
A1: PLANNING AND SCOPING CHECKLIST
A3: Step | B3: Activity | C3: Responsible | D3: Status | E3: Notes
A4: P-01 | B4: Confirm engagement trigger and regulatory basis
A5: P-02 | B5: Issue engagement letter with scope, timeline, and deliverables
A6: P-03 | B6: Confirm IESP team qualifications and independence (Part C compliance)
A7: P-04 | B7: Issue Document Request List (DRL) to the FI
A8: P-05 | B8: Obtain and review prior assessment reports and remediation status
A9: P-06 | B9: Identify platforms/CSPs in scope and complete scoping sheet
A10: P-07 | B10: Identify critical systems/workloads in scope
A11: P-08 | B11: Define assessment period and sampling approach
A12: P-09 | B12: Determine engagement mode: design adequacy (pre-impl) or operating effectiveness (attestation)
A13: P-10 | B13: Determine if higher-risk services criteria apply (customer data, cross-border)
A14: P-11 | B14: Schedule site visits / remote assessment sessions
A15: P-12 | B15: Conduct kick-off meeting with FI management
... A17: P-14 | B17: Finalise scoping memorandum

Sheet DCRA Assessment
A1: BNM Ref | B1: Ref | C1: Level | D1: Control Domain | E1: Sub-Procedure | F1: Assessment Procedures | G1: Expected Evidence | H1: Method | I1: Procedures Performed | J1: Evidence Obtained | K1: Evidence Ref | L1: Observations | M1: Conclusion | N1: Recommendations
A2: Domain 1 — DC Resilience and Availability Objectives (10.24)
A3: DC resilience objectives must align with business recovery requirements. Expect quantified targets (availability %, RTO, RPO) approved by committee. Misaligned objectives mean the DC cannot support business recovery.
A4: 10.24 | B4: DCRA-01 | C4: ORG | D4: DC Resilience Objectives | E4: Resilience targets aligned with business recovery requirements
A5: 10.24 | B5: DCRA-01.1 | E5: Objectives alignment and quantified targets | F5: 1. Obtain DC resilience strategy. 2. Extract resilience targets (availability %, RTO, RPO). 3. Compare against approved business recovery objectives. 4. Check targets approved by appropriate committee. 5. Verify periodic review (annual or upon material change). | G5: DC resilience strategy; Business recovery objectives matrix; Committee approval minutes; Review records | H5: Inspection
A6: Domain 2 — Redundancy and Single Points of Failure (10.25)
A7: Critical infrastructure must have no single points of failure. Expect N+1 or 2N redundancy, diverse paths, tested failover. A single failure in power, cooling, or network can cause a DC outage.
A8: 10.25 | B8: DCRA-02 | C8: PLATFORM | D8: Redundancy and SPOF | E8: Redundant capacity, diverse paths, SPOF analysis, and failover testing
A9: 10.25 | B9: DCRA-02.1 | E9: Redundant capacity design | F9: 1. Obtain redundancy design (N+1, 2N, 2N+1). 2. For each critical layer (power, cooling, network), confirm redundancy. 3. Verify actual capacity against design through site inspection. 4. Check redundant capacity handles full load on failover. | G9: Redundancy design specs; Capacity planning reports; Site inspection observations | H9: Inspection / Observation
B10: DCRA-02.2 | E10: Multiple distribution paths | F10: 1. Review electrical single-line diagrams for dual feeds. 2. Review network diagrams for diverse carrier paths. 3. Confirm physical path diversity. 4. Verify through site walk. | G10: Electrical single-line diagrams; Network path diversity docs; Site walk observations | H10: Inspection / Observation
B11: DCRA-02.3 | E11: SPOF analysis | F11: 1. Obtain SPOF analysis per DC. 2. Walk through each SPOF and confirm mitigations. 3. Identify unrecognised SPOFs during independent walkthrough. 4. Check SPOF analysis periodically refreshed. | G11: SPOF analysis/register; Mitigation action plans; Site walk findings | H11: Inspection / Observation
B12: DCRA-02.4 | E12: Failover testing | F12: 1. Obtain failover test plans and results (UPS, generators, cooling, switches). 2. Review test frequency (at least annual). 3. Confirm tests simulate actual failure conditions. 4. Check test failures remediated. | G12: Failover test plans; Test result reports; Corrective action records | H12: Inspection
A13: Domain 3 — Physical Security and Environmental Controls (10.26)
A14: Physical security protects against unauthorised access and environmental threats. Expect multi-layered access, environmental monitoring, fire suppression, hazard assessment. Physical compromise bypasses all logical controls.
A15: 10.26 | B15: DCRA-03 | C15: PLATFORM | D15: Physical Security & Environmental | E15: Multi-layered physical access, environmental monitoring, fire suppression, and hazard assessment
A16: 10.26 | B16: DCRA-03.1 | E16: Dedicated space and physical separation | F16: 1. Confirm DC in dedicated space. 2. Verify physical separation from public areas. 3. Check walls extend true floor to true ceiling. | G16: Site inspection observations; Building layout plans; Lease/facility agreements | H16: Observation
A17: 10.26 | B17: DCRA-03.2 | E17: Multi-layered access controls | F17: 1. Walk access path from perimeter to rack. 2. Verify independent controls at each layer. 3. Test access mechanisms. 4. Review provisioning/de-provisioning. 5. Sample-check access list against HR for terminated staff. | G17: Physical security policy; Access control config; Access list vs HR reconciliation; Site walk observations | H17: Inspection / Observation
A18: 10.26 | B18: DCRA-03.3 | E18: Disaster-prone location assessment | F18: 1. Obtain site risk assessment (flood, earthquake, lightning). 2. Cross-reference against hazard maps. 3. Verify mitigations. 4. Check assessment periodically updated. | G18: Site risk assessment; Hazard map cross-reference; Mitigation evidence | H18: Inspection
A19: 10.26 | B19: DCRA-03.4 | E19: Electrical infrastructure | F19: 1. Review UPS configuration (N+1 or 2N). 2. Verify UPS runtime (min 15 min). 3. Confirm generator auto-start and fuel autonomy (48-72 hrs). 4. Check ATS operation and tests. 5. Verify fuel replenishment contracts. | G19: UPS specs and test reports; Generator load test reports; ATS test records; Fuel supply contracts | H19: Inspection / Observation
A20: 10.26 | B20: DCRA-03.5 | E20: Thermal management | F20: 1. Review cooling design (N+1 min). 2. Check cooling load vs capacity. 3. Verify rack-level monitoring. 4. Confirm alerting thresholds. 5. Review hot/cold aisle containment. | G20: Cooling design docs; Capacity reports; Monitoring config; Alert thresholds | H20: Inspection / Observation
A21: 10.26 | B21: DCRA-03.6 | E21: Fire suppression and monitoring | F21: 1. Confirm VESDA or equivalent. 2. Verify gas-based suppression with current inspections. 3. Check water leak detection. 4. Verify 24/7 monitoring and alerting. 5. Review environmental incident response procedures. | G21: Fire suppression certificates; VESDA config; Water leak detection; Monitoring dashboard; Environmental IR procedures | H21: Inspection / Observation
B22: DCRA-03.7 | E22: Hardware lifecycle management | F22: 1. Obtain hardware asset register. 2. Sample-check physical assets against register. 3. Verify EOL/EOS hardware tracked with replacement plan. 4. Check secure data destruction for decommissioned equipment. | G22: Hardware asset register; Physical verification; EOL/EOS tracker; Data destruction certificates | H22: Inspection / Observation
A23: Domain 4 — DC Operations and Control Procedures (10.27)
A24: Operational controls ensure stable, monitored DC operations. Expect automated monitoring, controlled changes, incident management with RCA. Uncontrolled operations lead to avoidable outages.
A25: 10.27 | B25: DCRA-04 | C25: PLATFORM | D25: DC Operations | E25: Automated monitoring, batch processing, change management, and incident handling
A26: 10.27 | B26: DCRA-04.1 | E26: Automated monitoring | F26: 1. Obtain monitoring tool inventory (DCIM, BMS, network). 2. Verify coverage of critical parameters. 3. Test alerts for threshold breaches. 4. Confirm NOC/SOC integration. | G26: Tool inventory; Monitoring coverage matrix; Sample alerts; NOC/SOC integration | H26: Inspection
A27: 10.27 | B27: DCRA-04.2 | E27: Batch processing controls | F27: 1. Obtain batch job procedures. 2. Verify jobs have defined run windows, dependencies, error handling. 3. Review failure logs (3 months). 4. Check schedule changes controlled. | G27: Batch scheduling procedures; Job scheduler config; Failure logs; Change approval records | H27: Inspection
A28: 10.27 | B28: DCRA-04.3 | E28: Change management | F28: 1. Obtain DC change management procedure. 2. Sample 10 infrastructure changes. 3. Verify full lifecycle (request through post-impl review). 4. Check emergency changes follow defined process. | G28: Change management procedure; 10 sampled change records; Emergency change records | H28: Inspection
A29: 10.27 | B29: DCRA-04.4 | E29: Error and incident handling | F29: 1. Obtain DC incident management procedure. 2. Review incident log (6 months). 3. Verify RCA for significant incidents. 4. Check RCA findings led to preventive actions. | G29: Incident management procedure; Incident log (6 months); RCA reports; Preventive action tracker | H29: Inspection
A30: Domain 5 — Segregation of Incompatible Activities (10.28)
A31: Segregation prevents unauthorised changes and maintains environment integrity. Expect production isolation, controlled vendor access, SoD enforcement. Without segregation, a single actor can compromise production.
A32: 10.28 | B32: DCRA-05 | C32: PLATFORM | D32: Segregation | E32: Vendor access controls, production segregation, and segregation of duties
A33: 10.28 | B33: DCRA-05.1 | E33: Vendor access controls | F33: 1. Review vendor/third-party access policy. 2. Check pre-approved access requests. 3. Verify escort requirements. 4. Sample-check vendor access logs. 5. Confirm access revoked promptly. | G33: Vendor access policy; Access request forms; Escort logs; Access log reconciliation | H33: Inspection
B34: DCRA-05.2 | E34: Production segregation | F34: 1. Review logical and physical segregation (prod vs non-prod). 2. Verify developers have no direct production access. 3. Check network segmentation. 4. Confirm non-prod data masked. | G34: Environment segregation architecture; Access control matrices; Network segmentation; Data masking procedures | H34: Inspection
B35: DCRA-05.3 | E35: Segregation of duties | F35: 1. Obtain DC operations RACI. 2. Verify incompatible duties separated. 3. Check privileged access limited and monitored. 4. Review privileged access usage logs (3 months). | G35: RACI matrix; Role definitions; Privileged access list; Privileged access usage logs | H35: Inspection

Sheet Appendix 7 Part D
A1: BNM Ref | B1: Ref | C1: Level | D1: Control Domain | E1: Sub-Procedure | F1: Assessment Procedures | G1: Expected Evidence | H1: Method | I1: Procedures Performed | J1: Evidence Obtained | K1: Evidence Ref | L1: Observations | M1: Conclusion | N1: Recommendations
A2: Item 1(a) — Access Control
A3: Access control is foundational — who can access what. Expect policy-driven provisioning, periodic reviews, PAM controls, timely revocation. Excessive access is the most common audit finding.
A4: App7-D1(a) | B4: PD-01 | C4: ORG | D4: Access Control | E4: Access control policies, provisioning, privileged access, and periodic review
A5: App7-D1(a)(i) | B5: PD-01.1 | E5: Access control policies and mechanisms | F5: 1. Obtain the FI's access control policy and supporting standards. 2. Verify policy covers user registration, de-registration, access provisioning, and privilege management. 3. Sample 20 user accounts — verify access rights are consistent with job roles (least privilege). 4. Check that access reviews are performed periodically (quarterly for privileged, semi-annually for standard). 5. Verify access revocation upon termination — sample 10 recent leavers/transfers. | G5: Access control policy; User access provisioning records; Access review reports; HR leaver/transfer list vs. access revocation logs | H5: Inspection
A6: App7-D1(a)(ii) | B6: PD-01.2 | E6: Privileged access management | F6: 1. Obtain the PAM policy or standard. 2. Obtain the list of all privileged accounts (system admin, DBA, root, domain admin). 3. Verify privileged accounts are individually assigned or vault-managed with session recording. 4. Check that privileged access is time-bound and subject to approval workflow. 5. Review privileged session logs for the past 3 months for anomalies. | G6: PAM policy; Privileged account inventory; PAM tool configuration and logs; Session recording samples | H6: Inspection
A7: Item 1(b) — Physical and Environmental Security
A8: Physical controls protect technology assets from unauthorised access and environmental threats. Expect multi-layered access, CCTV, environmental monitoring. Physical compromise bypasses logical controls.
A9: App7-D1(b) | B9: PD-02 | C9: ORG | D9: Physical Security | E9: Physical access controls and environmental protection for technology assets
A10: App7-D1(b)(i) | B10: PD-02.1 | E10: Physical security controls | F10: 1. Identify all sensitive areas (data centres, server rooms, network rooms). 2. Verify multi-layered physical access controls (badge, biometric, PIN). 3. Review visitor management procedures. 4. Verify CCTV coverage with minimum 90-day retention. 5. Sample-check physical access logs against approved access lists. | G10: Physical security policy; Access control system config; Visitor logs; CCTV coverage map; Physical access log reconciliation | H10: Inspection / Observation
A11: App7-D1(b)(ii) | B11: PD-02.2 | E11: Environmental controls | F11: 1. Verify fire detection and suppression systems are current on inspections. 2. Check water leak detection. 3. Verify temperature and humidity monitoring with alerts. 4. Confirm environmental incident response procedures are tested. | G11: Fire system inspection certificates; Water leak detection layout; Environmental monitoring dashboards; Incident response test records | H11: Inspection / Observation
A12: Item 1(c) — Operations Security
A13: Operational controls ensure systems are managed securely. Expect documented procedures, controlled changes, tested backups, malware protection, vulnerability management. Operational failures cause avoidable incidents.
A14: App7-D1(c) | B14: PD-03 | C14: ORG | D14: Operations Security | E14: Operational procedures, change management, backup, malware protection, and vulnerability management
A15: App7-D1(c)(i) | B15: PD-03.1 | E15: Operational procedures and controls | F15: 1. Obtain documented operating procedures (change mgmt, capacity mgmt, backup, malware protection). 2. Verify change management — sample 10 changes with full lifecycle. 3. Verify backup procedures — confirm critical systems backed up and restore tested. 4. Verify anti-malware deployed with current signatures. | G15: Operating procedures; 10 sampled change records; Backup schedule and restore test results; Anti-malware deployment reports | H15: Inspection
A16: App7-D1(c)(ii) | B16: PD-03.2 | E16: Vulnerability management and patching | F16: 1. Obtain vulnerability management policy and patching SLAs. 2. Review most recent vulnerability scan results. 3. Check patch compliance rates. 4. Verify exceptions are formally risk-accepted. | G16: Vulnerability management policy; Scan reports; Patch compliance dashboard; Risk acceptance records | H16: Inspection
A17: Item 1(d) — Communications Security
A18: Network controls protect data in transit and network integrity. Expect segmentation, least-privilege firewall rules, encryption, IDS/IPS. Network compromise provides access to all connected systems.
A19: App7-D1(d) | B19: PD-04 | C19: ORG | D19: Communications Security | E19: Network security, segmentation, encryption of data in transit, and intrusion detection
A20: App7-D1(d)(i) | B20: PD-04.1 | E20: Network security and secure communications | F20: 1. Review network segmentation. 2. Verify firewall rules — sample 20 rules for least-privilege. 3. Confirm encryption of data in transit (TLS 1.2+). 4. Verify secure configuration of email, messaging, file transfer. 5. Check IDS/IPS deployed at critical boundaries. | G20: Network architecture diagram; Firewall rule base sample; TLS configuration; IDS/IPS deployment and alert records | H20: Inspection
A21: Item 1(e) — Incident Management
A22: Incident management ensures timely detection, response, and recovery. Expect 24/7 SOC, SIEM, IR playbooks, annual exercises. Without incident management, breaches escalate unchecked.
A23: App7-D1(e) | B23: PD-05 | C23: ORG | D23: Incident Management | E23: Incident detection, classification, response, RCA, and regulatory notification
A24: App7-D1(e)(i) | B24: PD-05.1 | E24: Incident management framework | F24: 1. Obtain incident management policy and procedures. 2. Verify incident classification scheme. 3. Review incident log for past 12 months. 4. Verify RCA for significant incidents with corrective actions. 5. Confirm regulatory notification procedures. | G24: Incident management policy; Classification matrix; Incident log (12 months); RCA reports; Regulatory notification records | H24: Inspection
A25: App7-D1(e)(ii) | B25: PD-05.2 | E25: Detection and response capabilities | F25: 1. Confirm SOC operates 24/7. 2. Verify SIEM deployment with critical log sources. 3. Sample 15 alerts — verify triage. 4. Confirm IR playbooks for common scenarios. 5. Verify annual IR drills/tabletop exercises. | G25: SOC operational documentation; SIEM log source inventory; 15 sampled alert records; IR playbooks; Drill/tabletop reports | H25: Inspection / Inquiry
A26: Item 1(f) — Business Continuity
A27: Business continuity ensures operations continue during disruptions. Expect BCP/DRP with cyber scenarios, tested DR including security controls, redundant security infrastructure. Untested DR fails when needed.
A28: App7-D1(f) | B28: PD-06 | C28: ORG | D28: Business Continuity | E28: Security in BCP/DRP, DR testing with security controls, and redundancy of security infrastructure
A29: App7-D1(f)(i) | B29: PD-06.1 | E29: Security in BCP/DRP | F29: 1. Obtain BCP and IT DRP. 2. Verify security requirements addressed in BCP/DRP. 3. Check BCP/DRP includes cyber incident scenarios. 4. Verify recovery procedures include security validation. | G29: BCP and IT DRP; Security requirements in BCP/DRP; Cyber incident scenarios; Recovery security validation checklists | H29: Inspection
A30: App7-D1(f)(ii) | B30: PD-06.2 | E30: BCP/DRP testing with security controls | F30: 1. Review most recent BCP/DRP test. 2. Verify security controls tested during DR exercise. 3. Confirm security findings remediated. 4. Verify DR site maintains equivalent security posture. | G30: BCP/DRP test plan and results; Security test components; DR site security assessment; Remediation tracker | H30: Inspection
A31: App7-D1(f)(iii) | B31: PD-06.3 | E31: Redundancy of security infrastructure | F31: 1. Identify critical security infrastructure and verify HA configuration. 2. Confirm failover tested. 3. Verify monitoring continues during DR. 4. Check licenses valid at DR site. | G31: Security infrastructure HA architecture; Failover test records; DR monitoring evidence; License/subscription records | H31: Inspection
A32: Item 2(a) — Customer Identity Authentication
A33: Customer authentication protects online services from unauthorised access. Expect MFA, secure sessions, strong cryptography, anti-session-fixation. Weak authentication directly exposes customers.
A34: App7-D2(a) | B34: PD-07 | C34: WORKLOAD | D34: Customer Authentication | E34: Session protection, MFA, credential storage, and cryptographic implementation
A35: App7-D2(a)(i) | B35: PD-07.1 | E35: Session and MITM protection | F35: 1. Review session management controls. 2. Verify TLS 1.2+, HSTS, certificate validity. 3. Confirm session tokens are cryptographically random with proper expiry. 4. Check anti-session-fixation controls. 5. Verify certificate pinning for mobile apps. | G35: TLS scan results; Session management config; Application security assessment; Mobile cert pinning evidence | H35: Inspection
A36: App7-D2(a)(ii) | B36: PD-07.2 | E36: Internal controls for online systems | F36: 1. Verify application hardening. 2. Review app security testing results (SAST, DAST, pen test). 3. Confirm database security controls. 4. Check segmentation from corporate network. | G36: Hardening standards; App security test reports; Database security config; Network segmentation evidence | H36: Inspection
A37: App7-D2(a)(iii) | B37: PD-07.3 | E37: Multi-level authentication | F37: 1. Review authentication architecture. 2. Verify MFA for login and high-risk transactions. 3. Check out-of-band authentication mechanisms. 4. Verify real-time verification for high-value transactions. 5. Assess authentication strength relative to transaction risk. | G37: Authentication architecture; MFA config; OTP/out-of-band mechanism; Risk-based authentication rules | H37: Inspection
A38: App7-D2(a)(iv) | B38: PD-07.4 | E38: Session handling and credential storage | F38: 1. Verify session timeouts (idle and absolute). 2. Confirm concurrent session controls. 3. Verify credentials stored with strong hashing (bcrypt, Argon2). 4. Check auth database access-restricted and encrypted. 5. Review account lockout configuration. | G38: Session management config; Password hashing evidence; Auth database access controls; Account lockout config | H38: Inspection
A39: App7-D2(a)(v) | B39: PD-07.5 | E39: Cryptographic implementation | F39: 1. Review cryptographic standards (AES-256, RSA-2048+, ECDSA P-256+). 2. Verify key management practices. 3. Check no deprecated algorithms. 4. Verify crypto implementation reviewed/tested. | G39: Cryptographic standards document; Key management procedures; HSM config; Crypto assessment results | H39: Inspection
A40: Item 2(b) — Transaction Authentication
...

Sheet Reporting & Attestation
A1: REPORTING AND ATTESTATION CHECKLIST
A3: Step | B3: Activity | C3: Responsible | D3: Status | E3: Notes
A4: R-01 | B4: Consolidate all test results — compile conclusions from all domain rows across assessment sheets
A5: R-02 | B5: Assign risk ratings (High/Medium/Low) to each finding based on likelihood and impact
A6: R-03 | B6: Map findings to specific regulatory references (Appendix clauses, Part D items)
A7: R-04 | B7: Draft recommendations with specific remediation steps, responsible parties, and timelines
A8: R-05 | B8: Distinguish must-fix-before-go-live findings from post-launch improvements (for pre-impl)
A9: R-06 | B9: Conduct quality assurance / peer review of working papers and findings
A10: R-07 | B10: Conduct findings walkthrough with FI management
A11: R-08 | B11: Incorporate management responses and agreed action plans
A12: R-09 | B12: Form Part C attestation opinion: Type A (Clean), Type B (With Exceptions), or Type C (Adverse)
A13: R-10 | B13: Prepare the formal report in Appendix 7 Part A format
A14: R-11 | B14: Confirm independence declaration and Part C compliance statement
A15: R-12 | B15: Obtain FI management sign-off on report and management action plans
... A19: R-16 | B19: Issue final signed report

Sheet Part C Self-Assessment
A1: APPENDIX 7 PART C — IESP SELF-ASSESSMENT
A2: The IESP must comply with these 6 requirements. Complete this self-assessment before issuing the report.
A4: # | B4: Requirement | C4: Assessment Criteria | D4: Evidence / Justification | E4: Compliant? | F4: Notes
A5: 1 | B5: Independence | C5: The IESP is independent of the FI's technology operations and the systems/services being assessed. No conflicts of interest exist between the IESP and the FI.
A6: 2 | B6: Competence | C6: The IESP team has relevant professional qualifications (CISA, CISSP, CCSP, CSP-specific certs), certifications, and experience in the subject matter being assessed.
A7: 3 | B7: Scope | C7: The assessment covers ALL areas specified in the relevant appendix (Appendix 10, Appendix 9, or Part D as applicable). No required areas were excluded without documented justification.
A8: 4 | B8: Methodology | C8: The IESP uses a systematic, risk-based assessment methodology with clear criteria for evaluating controls. The methodology is documented and consistently applied.
A9: 5 | B9: Reporting | C9: Findings are reported in the Appendix 7 Part A format with clear risk ratings and actionable recommendations. The report is complete, accurate, and traceable to evidence.
A10: 6 | B10: Quality Assurance | C10: Internal QA processes were followed, including peer review of assessment work by a qualified reviewer who did not perform the assessment.
A12: SIGN-OFF
A13: Lead Assessor: | B13: ________________________ | D13: Date: | E13: ______________
A14: Quality Reviewer: | B14: ________________________ | D14: Date: | E14: ______________

Sheet Scoring Dashboard
A1: SCORING DASHBOARD
A3: Conclusions are at the DOMAIN level only (Ref pattern: XX-NN without a dot). Sub-item rows (XX-NN.N) have observations but no conclusion.
A5: OVERALL SUMMARY
A6: Metric | B6: Value
A7: Total Compliant | B7: =SUM(B21:B22)
A8: Total Partially Compliant | B8: =SUM(C21:C22)
A9: Total Non-Compliant | B9: =SUM(D21:D22)
A10: Total N/A | B10: =SUM(E21:E22)
A11: Total Not Assessed | B11: =SUM(F21:F22)
A12: Total Control Domains | B12: =SUM(G21:G22)
A13: Overall Compliance % | B13: =IF((B12-B10-B11)=0,"—",B7/(B12-B10-B11))
A15: PART C OPINION INDICATOR
A16: Opinion Type | B16: =IF(B9>5,"Type C (Adverse)",IF(B9>0,"Type B (With Exceptions)",IF(B8<=3,"Type A (Clean)","Type B (With Exceptions)")))
A17: Criteria: | B17: Type A (Clean): NC=0 and PC<=3 | Type B (With Exceptions): NC>0 and NC<=5 | Type C (Adverse): NC>5
A19: PER-SHEET BREAKDOWN
A20: Sheet | B20: Compliant | C20: Partially Compliant | D20: Non-Compliant | E20: N/A | F20: Not Assessed | G20: Total Domains | H20: Compliance %
A21: DCRA Assessment | B21: =COUNTIF('DCRA Assessment'!M:M,"Compliant") | C21: =COUNTIF('DCRA Assessment'!M:M,"Partially Compliant") | D21: =COUNTIF('DCRA Assessment'!M:M,"Non-Compliant") | E21: =COUNTIF('DCRA Assessment'!M:M,"N/A") | F21: =COUNTIFS('DCRA Assessment'!B:B,"<>",'DCRA Assessment'!C:C,"<>",'DCRA Assessment'!M:M,"=")-COUNTIF('DCRA Assessment'!B:B,"Ref") | G21: =COUNTIFS('DCRA Assessment'!B:B,"<>",'DCRA Assessment'!C:C,"<>")-COUNTIF('DCRA Assessment'!B:B,"Ref") | H21: =IF((G21-E21-F21)=0,"—",B21/(G21-E21-F21))
A22: Appendix 7 Part D | B22: =COUNTIF('Appendix 7 Part D'!M:M,"Compliant") | C22: =COUNTIF('Appendix 7 Part D'!M:M,"Partially Compliant") | D22: =COUNTIF('Appendix 7 Part D'!M:M,"Non-Compliant") | E22: =COUNTIF('Appendix 7 Part D'!M:M,"N/A") | F22: =COUNTIFS('Appendix 7 Part D'!B:B,"<>",'Appendix 7 Part D'!C:C,"<>",'Appendix 7 Part D'!M:M,"=")-COUNTIF('Appendix 7 Part D'!B:B,"Ref") | G22: =COUNTIFS('Appendix 7 Part D'!B:B,"<>",'Appendix 7 Part D'!C:C,"<>")-COUNTIF('Appendix 7 Part D'!B:B,"Ref") | H22: =IF((G22-E22-F22)=0,"—",B22/(G22-E22-F22))
A25: LEVEL BREAKDOWN
A26: Level | B26: Compliant | C26: Partially Compliant | D26: Non-Compliant | E26: N/A | F26: Not Assessed | G26: Total
A27: ORG | B27: =COUNTIFS('DCRA Assessment'!C:C,"ORG",'DCRA Assessment'!M:M,"Compliant")+COUNTIFS('Appendix 7 Part D'!C:C,"ORG",'Appendix 7 Part D'!M:M,"Compliant") | C27: =COUNTIFS('DCRA Assessment'!C:C,"ORG",'DCRA Assessment'!M:M,"Partially Compliant")+COUNTIFS('Appendix 7 Part D'!C:C,"ORG",'Appendix 7 Part D'!M:M,"Partially Compliant") | D27: =COUNTIFS('DCRA Assessment'!C:C,"ORG",'DCRA Assessment'!M:M,"Non-Compliant")+COUNTIFS('Appendix 7 Part D'!C:C,"ORG",'Appendix 7 Part D'!M:M,"Non-Compliant") | E27: =COUNTIFS('DCRA Assessment'!C:C,"ORG",'DCRA Assessment'!M:M,"N/A")+COUNTIFS('Appendix 7 Part D'!C:C,"ORG",'Appendix 7 Part D'!M:M,"N/A") | F27: =COUNTIFS('DCRA Assessment'!C:C,"ORG",'DCRA Assessment'!M:M,"=")+COUNTIFS('Appendix 7 Part D'!C:C,"ORG",'Appendix 7 Part D'!M:M,"=") | G27: =SUM(B27:F27)
A28: PLATFORM | B28: =COUNTIFS('DCRA Assessment'!C:C,"PLATFORM",'DCRA Assessment'!M:M,"Compliant")+COUNTIFS('Appendix 7 Part D'!C:C,"PLATFORM",'Appendix 7 Part D'!M:M,"Compliant") | C28: =COUNTIFS('DCRA Assessment'!C:C,"PLATFORM",'DCRA Assessment'!M:M,"Partially Compliant")+COUNTIFS('Appendix 7 Part D'!C:C,"PLATFORM",'Appendix 7 Part D'!M:M,"Partially Compliant") | D28: =COUNTIFS('DCRA Assessment'!C:C,"PLATFORM",'DCRA Assessment'!M:M,"Non-Compliant")+COUNTIFS('Appendix 7 Part D'!C:C,"PLATFORM",'Appendix 7 Part D'!M:M,"Non-Compliant") | E28: =COUNTIFS('DCRA Assessment'!C:C,"PLATFORM",'DCRA Assessment'!M:M,"N/A")+COUNTIFS('Appendix 7 Part D'!C:C,"PLATFORM",'Appendix 7 Part D'!M:M,"N/A") | F28: =COUNTIFS('DCRA Assessment'!C:C,"PLATFORM",'DCRA Assessment'!M:M,"=")+COUNTIFS('Appendix 7 Part D'!C:C,"PLATFORM",'Appendix 7 Part D'!M:M,"=") | G28: =SUM(B28:F28)
A29: WORKLOAD | B29: =COUNTIFS('DCRA Assessment'!C:C,"WORKLOAD",'DCRA Assessment'!M:M,"Compliant")+COUNTIFS('Appendix 7 Part D'!C:C,"WORKLOAD",'Appendix 7 Part D'!M:M,"Compliant") | C29: =COUNTIFS('DCRA Assessment'!C:C,"WORKLOAD",'DCRA Assessment'!M:M,"Partially Compliant")+COUNTIFS('Appendix 7 Part D'!C:C,"WORKLOAD",'Appendix 7 Part D'!M:M,"Partially Compliant") | D29: =COUNTIFS('DCRA Assessment'!C:C,"WORKLOAD",'DCRA Assessment'!M:M,"Non-Compliant")+COUNTIFS('Appendix 7 Part D'!C:C,"WORKLOAD",'Appendix 7 Part D'!M:M,"Non-Compliant") | E29: =COUNTIFS('DCRA Assessment'!C:C,"WORKLOAD",'DCRA Assessment'!M:M,"N/A")+COUNTIFS('Appendix 7 Part D'!C:C,"WORKLOAD",'Appendix 7 Part D'!M:M,"N/A") | F29: =COUNTIFS('DCRA Assessment'!C:C,"WORKLOAD",'DCRA Assessment'!M:M,"=")+COUNTIFS('Appendix 7 Part D'!C:C,"WORKLOAD",'Appendix 7 Part D'!M:M,"=") | G29: =SUM(B29:F29)
