Workbook

Sheet Methodology & Approach
A1: INDEPENDENT ASSESSMENT — METHODOLOGY & APPROACH
A2: BNM RMiT IESP — Cloud Services Assessment
A4: ENGAGEMENT DETAILS
A5: Entity Name: | B5: [Entity Name]
A6: Engagement Type: | B6: Cloud IESP Assessment (Pre-Implementation or Independent Attestation)
A7: Regulatory Basis: | B7: Paragraph 17.1 / Appendix 7, mapped to Appendix 10
A8: Assessment Date: | B8: [DD/MM/YYYY]
A9: Assessment Period: | B9: [Start Date] to [End Date]
A10: Lead Assessor: | B10: [Name, Qualification]
A11: Engagement Reference: | B11: [Ref Number]
A12: Report Classification: | B12: Confidential (Sulit)
A14: SCOPE OF ASSESSMENT
A15: This assessment is conducted pursuant to BNM RMiT (BNM/RH/PD 028-98, 28 Nov 2025), Appendix 7 and Appendix 10. Where the cloud deployment involves emerging technology (AI/ML, DLT, IoT, etc.), the IESP-EmergingTech-WorkProgram.xlsx (Appendix 9) must also be used in conjunction with this workbook.
A16: Assessment covers: (1) Appendix 10 Part A — Cloud Governance (7 areas), (2) Appendix 10 Part B — Cloud Design and Control (14 areas), (3) Appendix 7 Part D — Minimum Controls.
A18: ENGAGEMENT MODE
A19: Design Adequacy (Pre-Implementation):
A20: Assess whether proposed/planned controls are designed to meet the requirement. Evidence is primarily documentary: architecture designs, policies, vendor assessments, staging test results.
A21: Operating Effectiveness (Independent Attestation):
A22: Assess whether controls operated effectively during the assessment period. Evidence is observation, sampling, re-performance, system-generated logs. Requires defined sampling methodology.
A24: ASSESSMENT LEVELS
A25: ORG | B25: Organisation-level. Assessed once per engagement (policies, governance, frameworks).
A26: PLATFORM | B26: Platform/CSP-level. Assessed per platform in scope (configurations, controls per CSP).
A27: WORKLOAD | B27: System/application-level. Assessed per critical system using sampling.
A29: ASSESSMENT METHODS
A30: Inspection | B30: Examination of documents, records, policies, configurations, and tangible evidence.
A31: Inquiry | B31: Interviews with management, process owners, and staff.
A32: Observation | B32: Direct observation of processes, systems, and activities.
A33: Confirmation | B33: Verification with external or independent parties.
A34: Re-performance | B34: IESP independently re-performs the control procedure.
A36: CONCLUSION SCALE
A37: Compliant | B37: Control fully implemented and operating effectively. Evidence supports regulatory criteria are met.
A38: Partially Compliant | B38: Implemented but with gaps in scope, coverage, documentation, or effectiveness.
A39: Non-Compliant | B39: Absent, fundamentally deficient, or not operating. Regulatory criteria not met.
A40: N/A | B40: Not applicable to entity's operations. Justification documented.
A42: EVIDENCE HIERARCHY (prefer higher-ranked)
A43: Rank 1 | B43: Direct observation — IESP directly observes control in operation
A44: Rank 2 | B44: Independent confirmation — Third-party evidence (SOC 2, certifications)
A45: Rank 3 | B45: System-generated — Logs, configurations without manual intervention
A46: Rank 4 | B46: Re-performance — IESP re-performs control procedure
A47: Rank 5 | B47: Documentary — Policies, procedures, meeting minutes
...

Sheet Scoping
A1: ENGAGEMENT SCOPING — BNM RMiT IESP — Cloud Services Assessment
A3: Note: Where the cloud deployment involves emerging technology (AI/ML, DLT, IoT, etc.), the IESP-EmergingTech-WorkProgram.xlsx (Appendix 9) must also be used in conjunction with this workbook.
A5: ASSESSMENT LEVELS
A6: ORG | B6: Organisation / Enterprise level. Assessed ONCE per engagement. Policies, frameworks, governance structures that apply across all platforms and systems.
A7: PLATFORM | B7: Platform / CSP level. Assessed PER PLATFORM in scope. If the FI uses AWS and Azure, repeat these test steps for each. Covers platform-specific configurations and controls.
A8: WORKLOAD | B8: Workload / Application / System level. Assessed PER CRITICAL SYSTEM in scope using sampling. Covers system-specific deployments, configurations, and arrangements.
A10: PLATFORMS / CSPs IN SCOPE
A11: # | B11: Platform / CSP | C11: Service Models (IaaS/PaaS/SaaS) | D11: Regions | E11: Contract Ref | F11: Notes
A12: 1
A13: 2
A14: 3
A15: 4
A16: 5
A18: CRITICAL SYSTEMS / WORKLOADS IN SCOPE
A19: # | B19: System / Application Name | C19: Platform | D19: Criticality | E19: Data Classification | F19: Notes
A20: 1
A21: 2
A22: 3
A23: 4
A24: 5
A25: 6
A26: 7
A27: 8
A28: 9
A29: 10
A31: SAMPLING APPROACH
A32: Assessment Period: | B32: [Start Date] to [End Date]
A33: User Access Samples: | B33: [e.g., 20 user accounts, 10 leavers/transfers]
A34: Change Management Samples: | B34: [e.g., 10 recent changes]
A35: Incident Samples: | B35: [e.g., 15 SOC alerts, all significant incidents in period]
A36: Firewall Rule Samples: | B36: [e.g., 20 rules]
A37: Configuration Samples: | B37: [e.g., 10 network devices]

Sheet Planning
A1: PLANNING AND SCOPING CHECKLIST
A3: Step | B3: Activity | C3: Responsible | D3: Status | E3: Notes
A4: P-01 | B4: Confirm engagement trigger and regulatory basis
A5: P-02 | B5: Issue engagement letter with scope, timeline, and deliverables
A6: P-03 | B6: Confirm IESP team qualifications and independence (Part C compliance)
A7: P-04 | B7: Issue Document Request List (DRL) to the FI
A8: P-05 | B8: Obtain and review prior assessment reports and remediation status
A9: P-06 | B9: Identify platforms/CSPs in scope and complete scoping sheet
A10: P-07 | B10: Identify critical systems/workloads in scope
A11: P-08 | B11: Define assessment period and sampling approach
A12: P-09 | B12: Determine engagement mode: design adequacy (pre-impl) or operating effectiveness (attestation)
A13: P-10 | B13: Determine if higher-risk services criteria apply (customer data, cross-border)
A14: P-11 | B14: Schedule site visits / remote assessment sessions
A15: P-12 | B15: Conduct kick-off meeting with FI management
... A17: P-14 | B17: Finalise scoping memorandum

Sheet App 10 Part A - Governance
A1: Ref | B1: Level | C1: Control | D1: Sub-Procedure | E1: Assessment Procedures | F1: Expected Evidence | G1: Method | H1: Procedures Performed | I1: Evidence Obtained | J1: Evidence Ref | K1: Observation / Findings | L1: Conclusion | M1: Recommendations
A2: A1 — Cloud Strategy
A3: BNM expects the FI's cloud strategy to be board-approved and aligned with business strategy. Assessor should find a documented strategy with clear workload eligibility criteria. Without this, cloud adoption is ad hoc and uncontrolled.
A4: CLD-01 | B4: ORG | C4: Cloud Strategy | D4: Board-approved cloud strategy | E4: 1. Obtain the FI's board-approved cloud strategy document. 2. Verify alignment with overall business and technology strategy. 3. Check that the strategy defines cloud-eligible vs non-eligible workloads. 4. Verify cloud-first, cloud-selective, or hybrid approach is defined and justified. 5. Check multi-cloud vs single-cloud considerations. 6. Verify regular review cycle (at least annual). | F4: Board-approved cloud strategy; Workload classification criteria; Cloud adoption roadmap; Strategy review records | G4: Inspection
A5: A2 — Roles and Responsibilities
A6: RMiT requires clear accountability for cloud operations, security, and governance. Expect a RACI matrix and documented shared responsibility model per CSP. Without defined roles, accountability gaps lead to control failures.
A7: CLD-02 | B7: ORG | C7: Roles & Responsibilities | D7: RACI and shared responsibility model | E7: 1. Obtain the cloud RACI matrix covering operations, security, and governance. 2. Verify cloud-specific roles are defined (cloud architect, cloud security engineer, cloud operations). 3. Check that the shared responsibility model with each CSP is documented and understood. 4. Verify escalation paths for cloud-related issues. 5. Check third-party management roles for cloud vendors. | F7: Cloud RACI matrix; Cloud role descriptions; Shared responsibility model per CSP; Org chart; Escalation procedures | G7: Inspection / Inquiry
A8: A3 — Policies and Procedures
A9: Cloud-specific policies operationalise the governance framework. Expect policies covering security, access, data, change, and incident response, communicated to staff. Without policies, controls lack a basis for enforcement.
A10: CLD-03 | B10: ORG | C10: Cloud Policy | D10: Cloud usage governance | E10: 1. Obtain the FI's cloud usage/security policy. 2. Verify it covers: approved CSPs, service/deployment models, data classification requirements, security baselines, approval workflow. 3. Check the policy is communicated to stakeholders. 4. Sample 3 recent cloud adoptions and check adherence. | F10: Cloud usage policy; Communication/awareness records; Sample cloud adoption records | G10: Inspection
A11: A4 — Risk Management
A12: BNM requires cloud risk assessment per 10.50 and Appendix 10. Expect a maintained risk register with risks assessed per CSP/service, reviewed annually. Without cloud-specific risk assessment, risk decisions are uninformed.
A13: CLD-04 | B13: ORG | C13: Cloud Risk Management | D13: Cloud-specific risk assessment | E13: 1. Obtain the FI's cloud risk assessment framework. 2. Verify it covers: data sovereignty, vendor lock-in, shared tenancy, supply chain, regulatory compliance. 3. Check risks are assessed per CSP and per service. 4. Verify risk assessment reviewed at least annually. | F13: Cloud risk assessment framework; Risk register (cloud section); Review/approval records | G13: Inspection
A14: CLD-05 | B14: ORG | C14: Cloud Risk Management | D14: Cloud risk appetite and tolerance | E14: 1. Check the FI has defined what can/cannot be placed in cloud. 2. Verify data classification rules for cloud placement. 3. Confirm risk appetite approved by board or designated committee. | F14: Cloud risk appetite statement; Data classification-to-cloud mapping; Board/committee approval | G14: Inspection
A15: A5 — Competency
A16: RMiT requires the FI to independently assess cloud posture. Expect cloud certifications, training plans, and succession planning. Without skilled personnel, the FI cannot manage cloud risk independently.
A17: CLD-06 | B17: ORG | C17: Competency | D17: Cloud team capability | E17: 1. Review cloud team structure, roles, and responsibilities. 2. Verify cloud certifications held by key personnel (AWS SAA/SAP, Azure AZ-500, GCP Professional, CCSP, CCSK). 3. Check training and development plan exists. 4. Assess whether the FI can independently assess CSP configurations. 5. Review succession planning for critical cloud roles. | F17: Cloud team org chart; Certification records; Training plan; Skills gap analysis; Succession plans | G17: Inspection / Inquiry
A18: A6 — Compliance
A19: Data residency, BNM access rights, and PDPA compliance are non-negotiable. Expect regulatory mapping and verified compliance controls. Non-compliance can result in regulatory action.
A20: CLD-07 | B20: ORG | C20: Compliance | D20: Regulatory mapping and compliance | E20: 1. Obtain the FI's regulatory compliance mapping for cloud (RMiT, PDPA, sectoral guidelines). 2. Verify data residency requirements identified and addressed. 3. Check cross-border data transmission requirements assessed. 4. Verify BNM access rights to data and systems preserved contractually and technically. 5. Confirm audit access rights preserved in CSP contracts. 6. Check compliance monitoring and reporting in place. | F20: Regulatory compliance mapping; Data residency analysis; Cross-border data flow assessment; CSP contract provisions for regulatory/audit access; Compliance monitoring reports | G20: Inspection
A21: A7 — Oversight
A22: Board-level visibility into cloud risk is required. Expect KPI/KRI reporting, SLA monitoring, and internal audit coverage. Without oversight, emerging risks go undetected.
A23: CLD-08 | B23: ORG | C23: Oversight | D23: Cloud performance and oversight framework | E23: 1. Review the FI's cloud performance monitoring framework (KPIs, KRIs). 2. Verify regular reporting to board/senior management on cloud operations. 3. Check CSP performance monitored against SLAs. 4. Verify internal audit coverage of cloud. 5. Check periodic review of cloud governance framework effectiveness. | F23: KPI/KRI definitions for cloud; Board/management reports; CSP SLA monitoring reports; Internal audit plan and reports; Governance framework review records | G23: Inspection
A24: CLD-09 | B24: PLATFORM | C24: Oversight | D24: CSP due diligence and certifications | E24: 1. Obtain due diligence reports for each in-scope CSP covering: financial viability, security capabilities, regulatory compliance, data residency, subcontracting, BCP. 2. Obtain current SOC 2 Type II, ISO 27001, CSA STAR reports per CSP. 3. Verify reports cover services used by the FI. 4. Review exceptions or deficiencies in reports. 5. Verify CUECs identified in SOC reports are implemented. 6. Verify due diligence refreshed at least annually. | F24: Due diligence reports per CSP; SOC 2 Type II reports; ISO 27001 certificates; CSA STAR reports; FI review of findings; CUEC implementation evidence | G24: Inspection
A25: CLD-10 | B25: PLATFORM | C25: Oversight | D25: CSP contract management | E25: 1. Review contracts with each in-scope CSP. 2. Check for: right to audit, data ownership/portability, data residency, breach notification, subcontracting controls, termination/exit provisions, BNM inspection access. 3. Verify contracts reviewed by legal and compliance. 4. Check ongoing CSP performance monitoring against SLAs. 5. Verify periodic service review meetings held. | F25: CSP contracts; Legal/compliance review records; Contract compliance checklist; SLA performance reports; Service review meeting minutes | G25: Inspection

Sheet App 10 Part B - Controls
A1: Ref | B1: Level | C1: Control | D1: Sub-Procedure | E1: Assessment Procedures | F1: Expected Evidence | G1: Method | H1: Procedures Performed | I1: Evidence Obtained | J1: Evidence Ref | K1: Observation / Findings | L1: Conclusion | M1: Recommendations
A2: B1 — Architecture Design
A3: Cloud architecture must support resilience and security. Expect multi-AZ for critical workloads, well-architected review, proper network segmentation. Poor architecture creates systemic risk.
A4: CLD-11 | B4: PLATFORM | C4: Architecture | D4: Cloud architecture design | E4: 1. Obtain cloud architecture design documents and diagrams. 2. Verify multi-AZ or multi-region deployment for critical workloads. 3. Check architecture follows well-architected framework principles. 4. Verify network architecture (VPC/VNET design, subnet segmentation, security groups, NACLs). 5. Confirm architecture reviewed by qualified cloud architects. 6. Verify landing zone / account structure design. | F4: Cloud architecture docs; Multi-AZ/region deployment evidence; Well-architected review; VPC/VNET design; Landing zone documentation | G4: Inspection
A5: B2 — Identity and Access Management
A6: Identity is the primary control plane in cloud. Expect MFA enforced, least-privilege policies, service account management, break-glass procedures. Weak IAM is the most common cloud compromise vector.
A7: CLD-12 | B7: PLATFORM | C7: Cloud IAM | D7: Identity and access management | E7: 1. Review cloud IAM architecture (identity federation, SSO, MFA). 2. Verify MFA enforced for all cloud console and API access. 3. Check least privilege — review IAM policies for overly permissive roles. 4. Verify privileged/admin access limited, separately managed, monitored. 5. Verify service accounts and API keys managed with rotation. 6. Check for unused/stale IAM accounts and access keys. 7. Review break-glass / emergency access procedures. | F7: IAM architecture; MFA enforcement config; IAM policy review; Privileged access inventory; Service account inventory; Stale account report; Break-glass procedures | G7: Inspection
A8: B3 — Data Protection
A9: Data classification and encryption are foundational. Expect classification tagging, encryption at rest/transit, key management strategy, DLP controls. Unprotected data in cloud is a regulatory breach.
A10: CLD-13 | B10: ORG | C10: Data Protection | D10: Data classification for cloud | E10: 1. Obtain the FI's data classification scheme as applied to cloud resources. 2. Verify classification tags are applied to cloud resources (storage, databases, compute). 3. Check that handling requirements are defined per classification level. 4. Verify controls are proportionate to classification. | F10: Data classification scheme; Cloud resource tagging evidence; Handling requirements per level; Classification compliance reports | G10: Inspection
A11: CLD-14 | B11: PLATFORM | C11: Data Protection | D11: Encryption and key management | E11: 1. Review cloud encryption and key management strategy. 2. Identify key ownership model (CSP-managed, CMK, BYOK). 3. Verify encryption at rest for all data stores. 4. Verify encryption in transit (TLS 1.2+) for all endpoints. 5. For CMK: verify key rotation schedule and access controls. 6. Verify DLP policies cover exfiltration detection, storage exposure, sharing controls. 7. Verify public access to cloud storage explicitly blocked. | F11: Encryption/key management policy; Key management config; Encryption-at-rest per data store; TLS config; DLP policy config; Cloud storage public access settings | G11: Inspection
A12: B4 — Network Security
A13: Cloud network controls replace traditional perimeter security. Expect VPC segmentation, WAF, DDoS protection, private connectivity, flow logging. Misconfigured cloud networking exposes services to the internet.
A14: CLD-15 | B14: PLATFORM | C14: Network Security | D14: Virtual network design and segmentation | E14: 1. Review VPC/VNet architecture and segmentation. 2. Verify security groups / network ACLs follow least-privilege. 3. Check private connectivity to cloud (Direct Connect, ExpressRoute, Interconnect). 4. Verify WAF deployed for internet-facing applications. 5. Verify DDoS protection enabled (L3/L4 and L7). 6. Check network flow logging enabled. 7. Verify API gateway security configuration. | F14: VPC/VNet architecture diagrams; Security group configs; Private connectivity architecture; WAF rules; DDoS protection config; Network flow log config; API gateway config | G14: Inspection
A15: B5 — Compute Security
A16: All compute resources must be hardened and patched. Expect hardening standards, container scanning, serverless permission controls, endpoint protection. Unpatched compute is the primary attack surface.
A17: CLD-16 | B17: PLATFORM | C17: Compute Security | D17: VM, container, and serverless security | E17: 1. Obtain VM/instance hardening standards and verify compliance. 2. Verify container images from approved registries and scanned for vulnerabilities. 3. Check containers run least-privilege (non-root, read-only FS). 4. Verify pod/container network policies enforce segmentation. 5. Check orchestrator hardened per CIS benchmarks. 6. Review serverless function permissions and secrets management. 7. Verify anti-malware / endpoint protection for cloud instances. 8. Check patch management for cloud compute resources. | F17: Hardening standards and compliance reports; Container image scanning reports; Runtime security config; Network policies; CIS benchmark reports; Serverless function permissions; Anti-malware deployment; Patch management reports | G17: Inspection
A18: B6 — Storage Security
A19: Cloud storage misconfigurations are a leading cause of data breaches. Expect public access blocked by default, access logging, lifecycle management. A single misconfigured bucket can expose all customer data.
A20: CLD-17 | B20: PLATFORM | C20: Storage Security | D20: Cloud storage controls | E20: 1. Review storage bucket/blob/object access policies. 2. Verify public access blocked by default (public access block enabled). 3. Check access logging enabled for storage services. 4. Verify encryption configuration for all storage types. 5. Review lifecycle management policies (retention, deletion). 6. Check versioning and deletion protection for critical data. 7. Verify cross-region replication security. | F20: Storage access policy configs; Public access block settings; Access logging config; Encryption settings; Lifecycle policies; Versioning/deletion protection; Cross-region replication config | G20: Inspection
A21: B7 — Logging and Monitoring
A22: Visibility into cloud activity is essential for detection and response. Expect cloud-native logging enabled, SIEM integration, CSPM deployed. Without logging, breaches go undetected.
A23: CLD-18 | B23: PLATFORM | C23: Logging & Monitoring | D23: Cloud security monitoring | E23: 1. Verify cloud-native audit logging enabled (CloudTrail, Activity Log, etc.). 2. Confirm centralised log aggregation (SIEM integration). 3. Check alert rules for security-relevant events. 4. Verify log retention aligned with regulatory requirements. 5. Check CSPM deployed to detect misconfigurations. 6. Review CSPM findings and remediation status. 7. Verify cost monitoring and anomaly detection. | F23: Cloud audit log config; SIEM integration; Alert rule configs; Log retention policies; CSPM config and findings; Cost monitoring dashboards | G23: Inspection
A24: B8 — Vulnerability Management
A25: Cloud resources must be scanned and patched systematically. Expect vulnerability scanning, patching SLAs, cloud-specific pen testing. Unmanaged vulnerabilities are exploitable at scale.
A26: CLD-19 | B26: PLATFORM | C26: Vulnerability Management | D26: Cloud vulnerability scanning and patching | E26: 1. Verify cloud resource vulnerability scanning (instances, containers, serverless). 2. Check CSP-native security posture management tools deployed. 3. Review patching SLAs and compliance rates for cloud resources. 4. Obtain most recent cloud environment penetration test report. 5. Verify pen testing complies with CSP policies. 6. Check remediation tracking and SLA adherence. | F26: Vulnerability scanning tool config and reports; Security posture management dashboards; Patching compliance reports; Cloud pen test report; Remediation tracker | G26: Inspection
A27: B9 — Change Management
A28: Infrastructure as Code and CI/CD must be governed. Expect version control, security gates, drift detection, approval workflows. Uncontrolled changes introduce misconfigurations.
A29: CLD-20 | B29: PLATFORM | C29: Change Management | D29: CI/CD and IaC governance | E29: 1. Review CI/CD pipeline architecture and security gates (SAST, DAST, SCA, container scanning). 2. Verify production deployment requires approval. 3. Check pipeline config is version-controlled and access-restricted. 4. Verify secrets not hardcoded. 5. Review IaC governance (code review, version control, approval). 6. Check IaC templates scanned for misconfigurations. 7. Verify configuration drift detection. 8. Confirm IaC state files stored securely. | F29: CI/CD architecture; Security gate config; Approval workflow; Pipeline access controls; IaC repository; IaC scanning tool; Drift detection; State file storage | G29: Inspection
A30: CLD-21 | B30: PLATFORM | C30: Change Management | D30: Cloud infrastructure change controls | E30: 1. Review cloud change management procedure. 2. Sample 10 recent cloud changes. 3. Verify each has: request, risk assessment, approval, implementation, post-implementation review. 4. Check security-critical changes (IAM, network, encryption) have enhanced approval. 5. Verify rollback capability and procedures. 6. Check emergency change procedures. | F30: Change management procedure; 10 sampled change records; Enhanced approval evidence; Rollback procedure; Emergency change records | G30: Inspection
A31: B10 — Incident Response
A32: Cloud incidents require adapted IR procedures. Expect cloud-specific playbooks, CSP coordination, forensic capability, SOC coverage. Standard IR procedures may not address cloud-specific scenarios.
A33: CLD-22 | B33: PLATFORM | C33: Incident Response | D33: Cloud incident response and forensics | E33: 1. Review IR plan for cloud-specific scenarios (account compromise, data breach, CSP outage, ransomware). 2. Verify procedures account for shared responsibility model. 3. Check CSP escalation contacts documented. 4. Verify forensic capability in cloud (snapshot, log preservation, evidence collection). 5. Check IR exercises include cloud scenarios. 6. Verify SOC coverage extends to cloud events with cloud-specific detection rules. | F33: Cloud IR procedures; CSP escalation contacts; Forensic procedures; IR exercise records; SIEM cloud log sources; Cloud detection rules; SOC analyst skill assessment | G33: Inspection / Inquiry
A34: B11 — Business Continuity
A35: Cloud DR must be tested, not assumed. Expect multi-AZ deployment, tested failover, defined RTO/RPO per workload. Cloud availability is not a substitute for tested DR.
A36: CLD-23 | B36: WORKLOAD | C36: Business Continuity | D36: Cloud DR and availability | E36: 1. Verify multi-AZ/multi-region deployment for each critical workload. 2. Review backup strategy and cross-region replication config. 3. Verify backup encryption and restore testing within 12 months. 4. Verify RTO/RPO defined and validated for cloud-hosted critical systems. 5. Check cloud DR/failover tested (cross-region failover). 6. Review CSP outage response procedures. 7. Verify backup monitoring — failed backups detected. | F36: Multi-AZ/region deployment evidence; Backup config and replication; Restore test results; RTO/RPO definitions; DR/failover test results; CSP outage procedures; Backup monitoring config | G36: Inspection
A37: B12 — Vendor Management
A38: CSP oversight is ongoing, not one-time. Expect due diligence, SLA monitoring, shared responsibility mapping, concentration risk assessment. Over-reliance on CSP assurances without independent verification is a risk.
A39: CLD-24 | B39: PLATFORM | C39: Vendor Management | D39: CSP assessment and oversight | E39: 1. Review CSP assessment documentation (financial stability, security, compliance). 2. Verify shared responsibility model documented and understood. 3. Check SLA monitoring (availability, performance, support response). 4. Review CSP risk profile assessment. 5. Check sub-processor management (CSP third parties). 6. Assess concentration risk — dependency on single/limited CSPs. | F39: CSP assessment docs; Shared responsibility mapping; SLA monitoring reports; CSP risk assessment; Sub-processor review; Concentration risk assessment | G39: Inspection
A40: B13 — Exit Strategy
...

Sheet Appendix 7 Part D
A1: Ref | B1: Level | C1: Control | D1: Sub-Procedure | E1: Assessment Procedures | F1: Expected Evidence | G1: Method | H1: Procedures Performed | I1: Evidence Obtained | J1: Evidence Ref | K1: Observation / Findings | L1: Conclusion | M1: Recommendations
A2: Item 1(a) — Access Control
A3: Access control is foundational — who can access what. Expect policy-driven provisioning, periodic reviews, PAM controls, timely revocation. Excessive access is the most common audit finding.
A4: PD-01 | B4: ORG | C4: Access Control | D4: Access control policies and mechanisms | E4: 1. Obtain the FI's access control policy and supporting standards. 2. Verify policy covers user registration, de-registration, access provisioning, and privilege management. 3. Sample 20 user accounts — verify access rights are consistent with job roles (least privilege). 4. Check that access reviews are performed periodically (quarterly for privileged, semi-annually for standard). 5. Verify access revocation upon termination — sample 10 recent leavers/transfers. | F4: Access control policy; User access provisioning records; Access review reports; HR leaver/transfer list vs. access revocation logs | G4: Inspection
A5: PD-02 | B5: ORG | C5: Access Control | D5: Privileged access management | E5: 1. Obtain the PAM policy or standard. 2. Obtain the list of all privileged accounts (system admin, DBA, root, domain admin). 3. Verify privileged accounts are individually assigned or vault-managed with session recording. 4. Check that privileged access is time-bound and subject to approval workflow. 5. Review privileged session logs for the past 3 months for anomalies. | F5: PAM policy; Privileged account inventory; PAM tool configuration and logs; Session recording samples | G5: Inspection
A6: Item 1(b) — Physical and Environmental Security
A7: Physical controls protect technology assets from unauthorised access and environmental threats. Expect multi-layered access, CCTV, environmental monitoring. Physical compromise bypasses logical controls.
A8: PD-03 | B8: ORG | C8: Physical Security | D8: Physical security controls | E8: 1. Identify all sensitive areas (data centres, server rooms, network rooms). 2. Verify multi-layered physical access controls (badge, biometric, PIN). 3. Review visitor management procedures. 4. Verify CCTV coverage with minimum 90-day retention. 5. Sample-check physical access logs against approved access lists. | F8: Physical security policy; Access control system config; Visitor logs; CCTV coverage map; Physical access log reconciliation | G8: Inspection / Observation
A9: PD-04 | B9: ORG | C9: Physical Security | D9: Environmental controls | E9: 1. Verify fire detection and suppression systems are current on inspections. 2. Check water leak detection. 3. Verify temperature and humidity monitoring with alerts. 4. Confirm environmental incident response procedures are tested. | F9: Fire system inspection certificates; Water leak detection layout; Environmental monitoring dashboards; Incident response test records | G9: Inspection / Observation
A10: Item 1(c) — Operations Security
A11: Operational controls ensure systems are managed securely. Expect documented procedures, controlled changes, tested backups, malware protection, vulnerability management. Operational failures cause avoidable incidents.
A12: PD-05 | B12: ORG | C12: Operations Security | D12: Operational procedures and controls | E12: 1. Obtain documented operating procedures (change mgmt, capacity mgmt, backup, malware protection). 2. Verify change management — sample 10 changes with full lifecycle. 3. Verify backup procedures — confirm critical systems backed up and restore tested. 4. Verify anti-malware deployed with current signatures. | F12: Operating procedures; 10 sampled change records; Backup schedule and restore test results; Anti-malware deployment reports | G12: Inspection
A13: PD-06 | B13: ORG | C13: Operations Security | D13: Vulnerability management and patching | E13: 1. Obtain vulnerability management policy and patching SLAs. 2. Review most recent vulnerability scan results. 3. Check patch compliance rates. 4. Verify exceptions are formally risk-accepted. | F13: Vulnerability management policy; Scan reports; Patch compliance dashboard; Risk acceptance records | G13: Inspection
A14: Item 1(d) — Communications Security
A15: Network controls protect data in transit and network integrity. Expect segmentation, least-privilege firewall rules, encryption, IDS/IPS. Network compromise provides access to all connected systems.
A16: PD-07 | B16: ORG | C16: Communications Security | D16: Network security and secure communications | E16: 1. Review network segmentation. 2. Verify firewall rules — sample 20 rules for least-privilege. 3. Confirm encryption of data in transit (TLS 1.2+). 4. Verify secure configuration of email, messaging, file transfer. 5. Check IDS/IPS deployed at critical boundaries. | F16: Network architecture diagram; Firewall rule base sample; TLS configuration; IDS/IPS deployment and alert records | G16: Inspection
A17: Item 1(e) — Incident Management
A18: Incident management ensures timely detection, response, and recovery. Expect 24/7 SOC, SIEM, IR playbooks, annual exercises. Without incident management, breaches escalate unchecked.
A19: PD-08 | B19: ORG | C19: Incident Management | D19: Incident management framework | E19: 1. Obtain incident management policy and procedures. 2. Verify incident classification scheme. 3. Review incident log for past 12 months. 4. Verify RCA for significant incidents with corrective actions. 5. Confirm regulatory notification procedures. | F19: Incident management policy; Classification matrix; Incident log (12 months); RCA reports; Regulatory notification records | G19: Inspection
A20: PD-09 | B20: ORG | C20: Incident Management | D20: Detection and response capabilities | E20: 1. Confirm SOC operates 24/7. 2. Verify SIEM deployment with critical log sources. 3. Sample 15 alerts — verify triage. 4. Confirm IR playbooks for common scenarios. 5. Verify annual IR drills/tabletop exercises. | F20: SOC operational documentation; SIEM log source inventory; 15 sampled alert records; IR playbooks; Drill/tabletop reports | G20: Inspection / Inquiry
A21: Item 1(f) — Business Continuity
A22: Business continuity ensures operations continue during disruptions. Expect BCP/DRP with cyber scenarios, tested DR including security controls, redundant security infrastructure. Untested DR fails when needed.
A23: PD-10 | B23: ORG | C23: Business Continuity | D23: Security in BCP/DRP | E23: 1. Obtain BCP and IT DRP. 2. Verify security requirements addressed in BCP/DRP. 3. Check BCP/DRP includes cyber incident scenarios. 4. Verify recovery procedures include security validation. | F23: BCP and IT DRP; Security requirements in BCP/DRP; Cyber incident scenarios; Recovery security validation checklists | G23: Inspection
A24: PD-11 | B24: ORG | C24: Business Continuity | D24: BCP/DRP testing with security controls | E24: 1. Review most recent BCP/DRP test. 2. Verify security controls tested during DR exercise. 3. Confirm security findings remediated. 4. Verify DR site maintains equivalent security posture. | F24: BCP/DRP test plan and results; Security test components; DR site security assessment; Remediation tracker | G24: Inspection
A25: PD-12 | B25: ORG | C25: Business Continuity | D25: Redundancy of security infrastructure | E25: 1. Identify critical security infrastructure and verify HA configuration. 2. Confirm failover tested. 3. Verify monitoring continues during DR. 4. Check licenses valid at DR site. | F25: Security infrastructure HA architecture; Failover test records; DR monitoring evidence; License/subscription records | G25: Inspection
A26: Item 2(a) — Customer Identity Authentication
A27: Customer authentication protects online services from unauthorised access. Expect MFA, secure sessions, strong cryptography, anti-session-fixation. Weak authentication directly exposes customers.
A28: PD-13 | B28: WORKLOAD | C28: Customer Authentication | D28: Session and MITM protection | E28: 1. Review session management controls. 2. Verify TLS 1.2+, HSTS, certificate validity. 3. Confirm session tokens are cryptographically random with proper expiry. 4. Check anti-session-fixation controls. 5. Verify certificate pinning for mobile apps. | F28: TLS scan results; Session management config; Application security assessment; Mobile cert pinning evidence | G28: Inspection
A29: PD-14 | B29: WORKLOAD | C29: Customer Authentication | D29: Internal controls for online systems | E29: 1. Verify application hardening. 2. Review app security testing results (SAST, DAST, pen test). 3. Confirm database security controls. 4. Check segmentation from corporate network. | F29: Hardening standards; App security test reports; Database security config; Network segmentation evidence | G29: Inspection
A30: PD-15 | B30: WORKLOAD | C30: Customer Authentication | D30: Multi-level authentication | E30: 1. Review authentication architecture. 2. Verify MFA for login and high-risk transactions. 3. Check out-of-band authentication mechanisms. 4. Verify real-time verification for high-value transactions. 5. Assess authentication strength relative to transaction risk. | F30: Authentication architecture; MFA config; OTP/out-of-band mechanism; Risk-based authentication rules | G30: Inspection
A31: PD-16 | B31: WORKLOAD | C31: Customer Authentication | D31: Session handling and credential storage | E31: 1. Verify session timeouts (idle and absolute). 2. Confirm concurrent session controls. 3. Verify credentials stored with strong hashing (bcrypt, Argon2). 4. Check auth database access-restricted and encrypted. 5. Review account lockout configuration. | F31: Session management config; Password hashing evidence; Auth database access controls; Account lockout config | G31: Inspection
A32: PD-17 | B32: ORG | C32: Customer Authentication | D32: Cryptographic implementation | E32: 1. Review cryptographic standards (AES-256, RSA-2048+, ECDSA P-256+). 2. Verify key management practices. 3. Check no deprecated algorithms. 4. Verify crypto implementation reviewed/tested. | F32: Cryptographic standards document; Key management procedures; HSM config; Crypto assessment results | G32: Inspection
A33: Item 2(b) — Transaction Authentication
A34: Transaction authentication ensures non-repudiation and integrity. Expect transaction signing, tamper-evident audit trails, mutual authentication. Without non-repudiation, disputes cannot be resolved.
A35: PD-18 | B35: WORKLOAD | C35: Transaction Authentication | D35: Proof of origin and integrity | E35: 1. Review transaction signing/MAC mechanisms. 2. Verify records include origin, timestamp, hash, integrity verification. 3. Confirm tamper-evident audit trails. 4. Check logs sufficient for dispute resolution. | F35: Transaction authentication mechanism; Sample transaction records; Audit trail controls; Log retention policy | G35: Inspection
A36: PD-19 | B36: WORKLOAD | C36: Transaction Authentication | D36: Secure delivery and mutual authentication | E36: 1. Verify delivery channel secured end-to-end. 2. Check alerts for high-risk transaction types. 3. Verify mutual authentication for B2B channels. 4. Review triggers for additional authentication. | F36: Channel security architecture; Transaction alert config; Mutual authentication implementation; Authentication trigger criteria | G36: Inspection
A37: Item 2(c) — Segregation of Duties
A38: SoD prevents single-person control over critical operations. Expect maker-checker, privileged user reviews, tamper-resistant authorisation. SoD failures enable fraud.
A39: PD-20 | B39: WORKLOAD | C39: Segregation of Duties | D39: Dual control for online transactions | E39: 1. Identify critical functions in online transaction systems. 2. Verify maker-checker for critical operations. 3. Review access control matrices — no single user can initiate and approve. 4. Verify unauthorised access detection. | F39: Access control matrices; Maker-checker config; Dual control workflow; Unauthorised access detection controls | G39: Inspection
A40: PD-21 | B40: WORKLOAD | C40: Segregation of Duties | D40: Authorisation database integrity | E40: 1. Verify authorisation database is tamper-resistant. 2. Confirm changes require approval and are logged. 3. Obtain privileged user list — verify quarterly review. 4. Check reviews result in revocation of unnecessary access. | F40: Auth database access controls; Change logs; Privileged user review records; Revocation evidence | G40: Inspection
...

Sheet Reporting & Attestation
A1: REPORTING AND ATTESTATION CHECKLIST
A3: Step | B3: Activity | C3: Responsible | D3: Status | E3: Notes
A4: R-01 | B4: Consolidate all test results — compile conclusions from all assessment sheets
A5: R-02 | B5: Assign risk ratings (High/Medium/Low) to each finding based on likelihood and impact
A6: R-03 | B6: Map findings to specific regulatory references (Appendix clauses, Part D items)
A7: R-04 | B7: Draft recommendations with specific remediation steps, responsible parties, and timelines
A8: R-05 | B8: Distinguish must-fix-before-go-live findings from post-launch improvements (for pre-impl)
A9: R-06 | B9: Conduct quality assurance / peer review of working papers and findings
A10: R-07 | B10: Conduct findings walkthrough with FI management
A11: R-08 | B11: Incorporate management responses and agreed action plans
A12: R-09 | B12: Form Part C attestation opinion: Type A (Clean), Type B (With Exceptions), or Type C (Adverse)
A13: R-10 | B13: Prepare the formal report in Appendix 7 Part A format
A14: R-11 | B14: Confirm independence declaration and Part C compliance statement
A15: R-12 | B15: Obtain FI management sign-off on report and management action plans
... A19: R-16 | B19: Issue final signed report

Sheet Part C Self-Assessment
A1: APPENDIX 7 PART C — IESP SELF-ASSESSMENT
A2: The IESP must comply with these 6 requirements. Complete this self-assessment before issuing the report.
A4: # | B4: Requirement | C4: Assessment Criteria | D4: Evidence / Justification | E4: Compliant? | F4: Notes
A5: 1 | B5: Independence | C5: The IESP is independent of the FI's technology operations and the systems/services being assessed. No conflicts of interest exist between the IESP and the FI.
A6: 2 | B6: Competence | C6: The IESP team has relevant professional qualifications (CISA, CISSP, CCSP, CSP-specific certs), certifications, and experience in the subject matter being assessed.
A7: 3 | B7: Scope | C7: The assessment covers ALL areas specified in the relevant appendix (Appendix 10, Appendix 9, or Part D as applicable). No required areas were excluded without documented justification.
A8: 4 | B8: Methodology | C8: The IESP uses a systematic, risk-based assessment methodology with clear criteria for evaluating controls. The methodology is documented and consistently applied.
A9: 5 | B9: Reporting | C9: Findings are reported in the Appendix 7 Part A format with clear risk ratings and actionable recommendations. The report is complete, accurate, and traceable to evidence.
A10: 6 | B10: Quality Assurance | C10: Internal QA processes were followed, including peer review of assessment work by a qualified reviewer who did not perform the assessment.
A12: SIGN-OFF
A13: Lead Assessor: | B13: ________________________ | D13: Date: | E13: ______________
A14: Quality Reviewer: | B14: ________________________ | D14: Date: | E14: ______________

Sheet Scoring Dashboard
A1: SCORING DASHBOARD
A3: OVERALL SUMMARY
A4: Metric | B4: Value
A5: Total Compliant | B5: =SUM(B19:B21)
A6: Total Partially Compliant | B6: =SUM(C19:C21)
A7: Total Non-Compliant | B7: =SUM(D19:D21)
A8: Total N/A | B8: =SUM(E19:E21)
A9: Total Not Assessed | B9: =SUM(F19:F21)
A10: Total Test Steps | B10: =SUM(G19:G21)
A11: Overall Compliance % | B11: =IF((B10-B8-B9)=0,"—",B5/(B10-B8-B9))
A13: PART C OPINION INDICATOR
A14: Opinion Type | B14: =IF(B7>5,"Type C (Adverse)",IF(B7>0,"Type B (With Exceptions)",IF(B6<=3,"Type A (Clean)","Type B (With Exceptions)")))
A15: Criteria: | B15: Type A (Clean): NC=0 and PC<=3 | Type B (With Exceptions): NC>0 and NC<=5 | Type C (Adverse): NC>5
A17: PER-SHEET BREAKDOWN
A18: Sheet | B18: Compliant | C18: Partially Compliant | D18: Non-Compliant | E18: N/A | F18: Not Assessed | G18: Total Steps | H18: Compliance %
A19: App 10 Part A - Governance | B19: =COUNTIF('App 10 Part A - Governance'!L:L,"Compliant") | C19: =COUNTIF('App 10 Part A - Governance'!L:L,"Partially Compliant") | D19: =COUNTIF('App 10 Part A - Governance'!L:L,"Non-Compliant") | E19: =COUNTIF('App 10 Part A - Governance'!L:L,"N/A") | F19: =COUNTIFS('App 10 Part A - Governance'!A:A,"<>",'App 10 Part A - Governance'!L:L,"=")-COUNTIF('App 10 Part A - Governance'!A:A,"Ref") | G19: =COUNTA('App 10 Part A - Governance'!A:A)-COUNTIF('App 10 Part A - Governance'!A:A,"Ref")-COUNTBLANK('App 10 Part A - Governance'!A1) | H19: =IF((G19-E19-F19)=0,"—",B19/(G19-E19-F19))
A20: App 10 Part B - Controls | B20: =COUNTIF('App 10 Part B - Controls'!L:L,"Compliant") | C20: =COUNTIF('App 10 Part B - Controls'!L:L,"Partially Compliant") | D20: =COUNTIF('App 10 Part B - Controls'!L:L,"Non-Compliant") | E20: =COUNTIF('App 10 Part B - Controls'!L:L,"N/A") | F20: =COUNTIFS('App 10 Part B - Controls'!A:A,"<>",'App 10 Part B - Controls'!L:L,"=")-COUNTIF('App 10 Part B - Controls'!A:A,"Ref") | G20: =COUNTA('App 10 Part B - Controls'!A:A)-COUNTIF('App 10 Part B - Controls'!A:A,"Ref")-COUNTBLANK('App 10 Part B - Controls'!A1) | H20: =IF((G20-E20-F20)=0,"—",B20/(G20-E20-F20))
A21: Appendix 7 Part D | B21: =COUNTIF('Appendix 7 Part D'!L:L,"Compliant") | C21: =COUNTIF('Appendix 7 Part D'!L:L,"Partially Compliant") | D21: =COUNTIF('Appendix 7 Part D'!L:L,"Non-Compliant") | E21: =COUNTIF('Appendix 7 Part D'!L:L,"N/A") | F21: =COUNTIFS('Appendix 7 Part D'!A:A,"<>",'Appendix 7 Part D'!L:L,"=")-COUNTIF('Appendix 7 Part D'!A:A,"Ref") | G21: =COUNTA('Appendix 7 Part D'!A:A)-COUNTIF('Appendix 7 Part D'!A:A,"Ref")-COUNTBLANK('Appendix 7 Part D'!A1) | H21: =IF((G21-E21-F21)=0,"—",B21/(G21-E21-F21))
A24: LEVEL BREAKDOWN
A25: Level | B25: Compliant | C25: Partially Compliant | D25: Non-Compliant | E25: N/A | F25: Not Assessed | G25: Total
A26: ORG | B26: =COUNTIFS('App 10 Part A - Governance'!B:B,"ORG",'App 10 Part A - Governance'!L:L,"Compliant")+COUNTIFS('App 10 Part B - Controls'!B:B,"ORG",'App 10 Part B - Controls'!L:L,"Compliant")+COUNTIFS('Appendix 7 Part D'!B:B,"ORG",'Appendix 7 Part D'!L:L,"Compliant") | C26: =COUNTIFS('App 10 Part A - Governance'!B:B,"ORG",'App 10 Part A - Governance'!L:L,"Partially Compliant")+COUNTIFS('App 10 Part B - Controls'!B:B,"ORG",'App 10 Part B - Controls'!L:L,"Partially Compliant")+COUNTIFS('Appendix 7 Part D'!B:B,"ORG",'Appendix 7 Part D'!L:L,"Partially Compliant") | D26: =COUNTIFS('App 10 Part A - Governance'!B:B,"ORG",'App 10 Part A - Governance'!L:L,"Non-Compliant")+COUNTIFS('App 10 Part B - Controls'!B:B,"ORG",'App 10 Part B - Controls'!L:L,"Non-Compliant")+COUNTIFS('Appendix 7 Part D'!B:B,"ORG",'Appendix 7 Part D'!L:L,"Non-Compliant") | E26: =COUNTIFS('App 10 Part A - Governance'!B:B,"ORG",'App 10 Part A - Governance'!L:L,"N/A")+COUNTIFS('App 10 Part B - Controls'!B:B,"ORG",'App 10 Part B - Controls'!L:L,"N/A")+COUNTIFS('Appendix 7 Part D'!B:B,"ORG",'Appendix 7 Part D'!L:L,"N/A") | F26: =COUNTIFS('App 10 Part A - Governance'!B:B,"ORG",'App 10 Part A - Governance'!L:L,"=")+COUNTIFS('App 10 Part B - Controls'!B:B,"ORG",'App 10 Part B - Controls'!L:L,"=")+COUNTIFS('Appendix 7 Part D'!B:B,"ORG",'Appendix 7 Part D'!L:L,"=") | G26: =SUM(B26:F26)
A27: PLATFORM | B27: =COUNTIFS('App 10 Part A - Governance'!B:B,"PLATFORM",'App 10 Part A - Governance'!L:L,"Compliant")+COUNTIFS('App 10 Part B - Controls'!B:B,"PLATFORM",'App 10 Part B - Controls'!L:L,"Compliant")+COUNTIFS('Appendix 7 Part D'!B:B,"PLATFORM",'Appendix 7 Part D'!L:L,"Compliant") | C27: =COUNTIFS('App 10 Part A - Governance'!B:B,"PLATFORM",'App 10 Part A - Governance'!L:L,"Partially Compliant")+COUNTIFS('App 10 Part B - Controls'!B:B,"PLATFORM",'App 10 Part B - Controls'!L:L,"Partially Compliant")+COUNTIFS('Appendix 7 Part D'!B:B,"PLATFORM",'Appendix 7 Part D'!L:L,"Partially Compliant") | D27: =COUNTIFS('App 10 Part A - Governance'!B:B,"PLATFORM",'App 10 Part A - Governance'!L:L,"Non-Compliant")+COUNTIFS('App 10 Part B - Controls'!B:B,"PLATFORM",'App 10 Part B - Controls'!L:L,"Non-Compliant")+COUNTIFS('Appendix 7 Part D'!B:B,"PLATFORM",'Appendix 7 Part D'!L:L,"Non-Compliant") | E27: =COUNTIFS('App 10 Part A - Governance'!B:B,"PLATFORM",'App 10 Part A - Governance'!L:L,"N/A")+COUNTIFS('App 10 Part B - Controls'!B:B,"PLATFORM",'App 10 Part B - Controls'!L:L,"N/A")+COUNTIFS('Appendix 7 Part D'!B:B,"PLATFORM",'Appendix 7 Part D'!L:L,"N/A") | F27: =COUNTIFS('App 10 Part A - Governance'!B:B,"PLATFORM",'App 10 Part A - Governance'!L:L,"=")+COUNTIFS('App 10 Part B - Controls'!B:B,"PLATFORM",'App 10 Part B - Controls'!L:L,"=")+COUNTIFS('Appendix 7 Part D'!B:B,"PLATFORM",'Appendix 7 Part D'!L:L,"=") | G27: =SUM(B27:F27)
A28: WORKLOAD | B28: =COUNTIFS('App 10 Part A - Governance'!B:B,"WORKLOAD",'App 10 Part A - Governance'!L:L,"Compliant")+COUNTIFS('App 10 Part B - Controls'!B:B,"WORKLOAD",'App 10 Part B - Controls'!L:L,"Compliant")+COUNTIFS('Appendix 7 Part D'!B:B,"WORKLOAD",'Appendix 7 Part D'!L:L,"Compliant") | C28: =COUNTIFS('App 10 Part A - Governance'!B:B,"WORKLOAD",'App 10 Part A - Governance'!L:L,"Partially Compliant")+COUNTIFS('App 10 Part B - Controls'!B:B,"WORKLOAD",'App 10 Part B - Controls'!L:L,"Partially Compliant")+COUNTIFS('Appendix 7 Part D'!B:B,"WORKLOAD",'Appendix 7 Part D'!L:L,"Partially Compliant") | D28: =COUNTIFS('App 10 Part A - Governance'!B:B,"WORKLOAD",'App 10 Part A - Governance'!L:L,"Non-Compliant")+COUNTIFS('App 10 Part B - Controls'!B:B,"WORKLOAD",'App 10 Part B - Controls'!L:L,"Non-Compliant")+COUNTIFS('Appendix 7 Part D'!B:B,"WORKLOAD",'Appendix 7 Part D'!L:L,"Non-Compliant") | E28: =COUNTIFS('App 10 Part A - Governance'!B:B,"WORKLOAD",'App 10 Part A - Governance'!L:L,"N/A")+COUNTIFS('App 10 Part B - Controls'!B:B,"WORKLOAD",'App 10 Part B - Controls'!L:L,"N/A")+COUNTIFS('Appendix 7 Part D'!B:B,"WORKLOAD",'Appendix 7 Part D'!L:L,"N/A") | F28: =COUNTIFS('App 10 Part A - Governance'!B:B,"WORKLOAD",'App 10 Part A - Governance'!L:L,"=")+COUNTIFS('App 10 Part B - Controls'!B:B,"WORKLOAD",'App 10 Part B - Controls'!L:L,"=")+COUNTIFS('Appendix 7 Part D'!B:B,"WORKLOAD",'Appendix 7 Part D'!L:L,"=") | G28: =SUM(B28:F28)
